[31mERROR[0m:    [29-01-2024 15:37:36] Failed to set chroma_server_nofile to 65535: current limit exceeds maximum limit nofile soft limit will remain at 10240
[32mINFO[0m:     [29-01-2024 15:37:36] Anonymized telemetry enabled. See                     https://docs.trychroma.com/telemetry for more information.
[36mDEBUG[0m:    [29-01-2024 15:37:36] Starting component System
[36mDEBUG[0m:    [29-01-2024 15:37:36] Starting component OpenTelemetryClient
[36mDEBUG[0m:    [29-01-2024 15:37:36] Starting component SimpleAssignmentPolicy
[36mDEBUG[0m:    [29-01-2024 15:37:36] Starting component SqliteDB
[36mDEBUG[0m:    [29-01-2024 15:37:36] Starting component Posthog
[36mDEBUG[0m:    [29-01-2024 15:37:36] Starting component LocalSegmentManager
[36mDEBUG[0m:    [29-01-2024 15:37:36] Starting component SegmentAPI
[32mINFO[0m:     [29-01-2024 15:37:36] Started server process [[36m63569[0m]
[32mINFO[0m:     [29-01-2024 15:37:36] Waiting for application startup.
[32mINFO[0m:     [29-01-2024 15:37:36] Application startup complete.
[32mINFO[0m:     [29-01-2024 15:37:36] Uvicorn running on [1mhttp://localhost:8000[0m (Press CTRL+C to quit)
[32mINFO[0m:     [29-01-2024 15:38:02] ::1:59537 - "POST /api/v1/collections?tenant=default_tenant&database=default_database HTTP/1.1" 200
[32mINFO[0m:     [29-01-2024 15:38:02] ::1:59538 - "POST /api/v1/collections/e1e16209-8f4d-461c-bc8b-6b4c5fd7829b/get HTTP/1.1" 200
[31mERROR[0m:    [29-01-2024 15:38:02] 
                You must provide either ids, where, or where_document to delete. If
                you want to delete all data in a collection you can delete the
                collection itself using the delete_collection method. Or alternatively,
                you can get() all the relevant ids and then delete them.
                
Traceback (most recent call last):
  File "/Library/Frameworks/Python.framework/Versions/3.10/lib/python3.10/site-packages/anyio/streams/memory.py", line 97, in receive
    return self.receive_nowait()
  File "/Library/Frameworks/Python.framework/Versions/3.10/lib/python3.10/site-packages/anyio/streams/memory.py", line 92, in receive_nowait
    raise WouldBlock
anyio.WouldBlock

During handling of the above exception, another exception occurred:

Traceback (most recent call last):
  File "/Library/Frameworks/Python.framework/Versions/3.10/lib/python3.10/site-packages/starlette/middleware/base.py", line 159, in call_next
    message = await recv_stream.receive()
  File "/Library/Frameworks/Python.framework/Versions/3.10/lib/python3.10/site-packages/anyio/streams/memory.py", line 112, in receive
    raise EndOfStream
anyio.EndOfStream

During handling of the above exception, another exception occurred:

Traceback (most recent call last):
  File "/Library/Frameworks/Python.framework/Versions/3.10/lib/python3.10/site-packages/chromadb/server/fastapi/__init__.py", line 80, in catch_exceptions_middleware
    return await call_next(request)
  File "/Library/Frameworks/Python.framework/Versions/3.10/lib/python3.10/site-packages/starlette/middleware/base.py", line 165, in call_next
    raise app_exc
  File "/Library/Frameworks/Python.framework/Versions/3.10/lib/python3.10/site-packages/starlette/middleware/base.py", line 151, in coro
    await self.app(scope, receive_or_disconnect, send_no_error)
  File "/Library/Frameworks/Python.framework/Versions/3.10/lib/python3.10/site-packages/starlette/middleware/base.py", line 189, in __call__
    with collapse_excgroups():
  File "/Library/Frameworks/Python.framework/Versions/3.10/lib/python3.10/contextlib.py", line 153, in __exit__
    self.gen.throw(typ, value, traceback)
  File "/Library/Frameworks/Python.framework/Versions/3.10/lib/python3.10/site-packages/starlette/_utils.py", line 91, in collapse_excgroups
    raise exc
  File "/Library/Frameworks/Python.framework/Versions/3.10/lib/python3.10/site-packages/starlette/middleware/base.py", line 191, in __call__
    response = await self.dispatch_func(request, call_next)
  File "/Library/Frameworks/Python.framework/Versions/3.10/lib/python3.10/site-packages/chromadb/server/fastapi/__init__.py", line 94, in check_http_version_middleware
    return await call_next(request)
  File "/Library/Frameworks/Python.framework/Versions/3.10/lib/python3.10/site-packages/starlette/middleware/base.py", line 165, in call_next
    raise app_exc
  File "/Library/Frameworks/Python.framework/Versions/3.10/lib/python3.10/site-packages/starlette/middleware/base.py", line 151, in coro
    await self.app(scope, receive_or_disconnect, send_no_error)
  File "/Library/Frameworks/Python.framework/Versions/3.10/lib/python3.10/site-packages/starlette/middleware/exceptions.py", line 62, in __call__
    await wrap_app_handling_exceptions(self.app, conn)(scope, receive, send)
  File "/Library/Frameworks/Python.framework/Versions/3.10/lib/python3.10/site-packages/starlette/_exception_handler.py", line 64, in wrapped_app
    raise exc
  File "/Library/Frameworks/Python.framework/Versions/3.10/lib/python3.10/site-packages/starlette/_exception_handler.py", line 53, in wrapped_app
    await app(scope, receive, sender)
  File "/Library/Frameworks/Python.framework/Versions/3.10/lib/python3.10/site-packages/starlette/routing.py", line 762, in __call__
    await self.middleware_stack(scope, receive, send)
  File "/Library/Frameworks/Python.framework/Versions/3.10/lib/python3.10/site-packages/starlette/routing.py", line 782, in app
    await route.handle(scope, receive, send)
  File "/Library/Frameworks/Python.framework/Versions/3.10/lib/python3.10/site-packages/starlette/routing.py", line 297, in handle
    await self.app(scope, receive, send)
  File "/Library/Frameworks/Python.framework/Versions/3.10/lib/python3.10/site-packages/starlette/routing.py", line 77, in app
    await wrap_app_handling_exceptions(app, request)(scope, receive, send)
  File "/Library/Frameworks/Python.framework/Versions/3.10/lib/python3.10/site-packages/starlette/_exception_handler.py", line 64, in wrapped_app
    raise exc
  File "/Library/Frameworks/Python.framework/Versions/3.10/lib/python3.10/site-packages/starlette/_exception_handler.py", line 53, in wrapped_app
    await app(scope, receive, sender)
  File "/Library/Frameworks/Python.framework/Versions/3.10/lib/python3.10/site-packages/starlette/routing.py", line 72, in app
    response = await func(request)
  File "/Library/Frameworks/Python.framework/Versions/3.10/lib/python3.10/site-packages/fastapi/routing.py", line 299, in app
    raise e
  File "/Library/Frameworks/Python.framework/Versions/3.10/lib/python3.10/site-packages/fastapi/routing.py", line 294, in app
    raw_response = await run_endpoint_function(
  File "/Library/Frameworks/Python.framework/Versions/3.10/lib/python3.10/site-packages/fastapi/routing.py", line 193, in run_endpoint_function
    return await run_in_threadpool(dependant.call, **values)
  File "/Library/Frameworks/Python.framework/Versions/3.10/lib/python3.10/site-packages/starlette/concurrency.py", line 40, in run_in_threadpool
    return await anyio.to_thread.run_sync(func, *args)
  File "/Library/Frameworks/Python.framework/Versions/3.10/lib/python3.10/site-packages/anyio/to_thread.py", line 56, in run_sync
    return await get_async_backend().run_sync_in_worker_thread(
  File "/Library/Frameworks/Python.framework/Versions/3.10/lib/python3.10/site-packages/anyio/_backends/_asyncio.py", line 2134, in run_sync_in_worker_thread
    return await future
  File "/Library/Frameworks/Python.framework/Versions/3.10/lib/python3.10/site-packages/anyio/_backends/_asyncio.py", line 851, in run
    result = context.run(func, *args)
  File "/Library/Frameworks/Python.framework/Versions/3.10/lib/python3.10/site-packages/chromadb/telemetry/opentelemetry/__init__.py", line 127, in wrapper
    return f(*args, **kwargs)
  File "/Library/Frameworks/Python.framework/Versions/3.10/lib/python3.10/site-packages/chromadb/auth/fastapi.py", line 234, in wrapped
    return f(*args, **kwargs)
  File "/Library/Frameworks/Python.framework/Versions/3.10/lib/python3.10/site-packages/chromadb/server/fastapi/__init__.py", line 568, in delete
    return self._api._delete(
  File "/Library/Frameworks/Python.framework/Versions/3.10/lib/python3.10/site-packages/chromadb/telemetry/opentelemetry/__init__.py", line 127, in wrapper
    return f(*args, **kwargs)
  File "/Library/Frameworks/Python.framework/Versions/3.10/lib/python3.10/site-packages/chromadb/api/segment.py", line 599, in _delete
    raise ValueError(
ValueError: 
                You must provide either ids, where, or where_document to delete. If
                you want to delete all data in a collection you can delete the
                collection itself using the delete_collection method. Or alternatively,
                you can get() all the relevant ids and then delete them.
                
[32mINFO[0m:     [29-01-2024 15:38:02] ::1:59537 - "POST /api/v1/collections/e1e16209-8f4d-461c-bc8b-6b4c5fd7829b/delete HTTP/1.1" 500
[31mERROR[0m:    [29-01-2024 15:40:30] Failed to set chroma_server_nofile to 65535: current limit exceeds maximum limit nofile soft limit will remain at 10240
[32mINFO[0m:     [29-01-2024 15:40:30] Anonymized telemetry enabled. See                     https://docs.trychroma.com/telemetry for more information.
[36mDEBUG[0m:    [29-01-2024 15:40:30] Starting component System
[36mDEBUG[0m:    [29-01-2024 15:40:30] Starting component OpenTelemetryClient
[36mDEBUG[0m:    [29-01-2024 15:40:30] Starting component SimpleAssignmentPolicy
[36mDEBUG[0m:    [29-01-2024 15:40:30] Starting component SqliteDB
[36mDEBUG[0m:    [29-01-2024 15:40:30] Starting component Posthog
[36mDEBUG[0m:    [29-01-2024 15:40:30] Starting component LocalSegmentManager
[36mDEBUG[0m:    [29-01-2024 15:40:30] Starting component SegmentAPI
[32mINFO[0m:     [29-01-2024 15:40:30] Started server process [[36m63775[0m]
[32mINFO[0m:     [29-01-2024 15:40:30] Waiting for application startup.
[32mINFO[0m:     [29-01-2024 15:40:30] Application startup complete.
[32mINFO[0m:     [29-01-2024 15:40:30] Uvicorn running on [1mhttp://localhost:8000[0m (Press CTRL+C to quit)
[32mINFO[0m:     [29-01-2024 15:41:19] ::1:60328 - "POST /api/v1/collections?tenant=default_tenant&database=default_database HTTP/1.1" 200
[32mINFO[0m:     [29-01-2024 15:41:19] ::1:60329 - "POST /api/v1/collections/e1e16209-8f4d-461c-bc8b-6b4c5fd7829b/get HTTP/1.1" 200
[31mERROR[0m:    [29-01-2024 15:41:19] 
                You must provide either ids, where, or where_document to delete. If
                you want to delete all data in a collection you can delete the
                collection itself using the delete_collection method. Or alternatively,
                you can get() all the relevant ids and then delete them.
                
Traceback (most recent call last):
  File "/Library/Frameworks/Python.framework/Versions/3.10/lib/python3.10/site-packages/anyio/streams/memory.py", line 97, in receive
    return self.receive_nowait()
  File "/Library/Frameworks/Python.framework/Versions/3.10/lib/python3.10/site-packages/anyio/streams/memory.py", line 92, in receive_nowait
    raise WouldBlock
anyio.WouldBlock

During handling of the above exception, another exception occurred:

Traceback (most recent call last):
  File "/Library/Frameworks/Python.framework/Versions/3.10/lib/python3.10/site-packages/starlette/middleware/base.py", line 159, in call_next
    message = await recv_stream.receive()
  File "/Library/Frameworks/Python.framework/Versions/3.10/lib/python3.10/site-packages/anyio/streams/memory.py", line 112, in receive
    raise EndOfStream
anyio.EndOfStream

During handling of the above exception, another exception occurred:

Traceback (most recent call last):
  File "/Library/Frameworks/Python.framework/Versions/3.10/lib/python3.10/site-packages/chromadb/server/fastapi/__init__.py", line 80, in catch_exceptions_middleware
    return await call_next(request)
  File "/Library/Frameworks/Python.framework/Versions/3.10/lib/python3.10/site-packages/starlette/middleware/base.py", line 165, in call_next
    raise app_exc
  File "/Library/Frameworks/Python.framework/Versions/3.10/lib/python3.10/site-packages/starlette/middleware/base.py", line 151, in coro
    await self.app(scope, receive_or_disconnect, send_no_error)
  File "/Library/Frameworks/Python.framework/Versions/3.10/lib/python3.10/site-packages/starlette/middleware/base.py", line 189, in __call__
    with collapse_excgroups():
  File "/Library/Frameworks/Python.framework/Versions/3.10/lib/python3.10/contextlib.py", line 153, in __exit__
    self.gen.throw(typ, value, traceback)
  File "/Library/Frameworks/Python.framework/Versions/3.10/lib/python3.10/site-packages/starlette/_utils.py", line 91, in collapse_excgroups
    raise exc
  File "/Library/Frameworks/Python.framework/Versions/3.10/lib/python3.10/site-packages/starlette/middleware/base.py", line 191, in __call__
    response = await self.dispatch_func(request, call_next)
  File "/Library/Frameworks/Python.framework/Versions/3.10/lib/python3.10/site-packages/chromadb/server/fastapi/__init__.py", line 94, in check_http_version_middleware
    return await call_next(request)
  File "/Library/Frameworks/Python.framework/Versions/3.10/lib/python3.10/site-packages/starlette/middleware/base.py", line 165, in call_next
    raise app_exc
  File "/Library/Frameworks/Python.framework/Versions/3.10/lib/python3.10/site-packages/starlette/middleware/base.py", line 151, in coro
    await self.app(scope, receive_or_disconnect, send_no_error)
  File "/Library/Frameworks/Python.framework/Versions/3.10/lib/python3.10/site-packages/starlette/middleware/exceptions.py", line 62, in __call__
    await wrap_app_handling_exceptions(self.app, conn)(scope, receive, send)
  File "/Library/Frameworks/Python.framework/Versions/3.10/lib/python3.10/site-packages/starlette/_exception_handler.py", line 64, in wrapped_app
    raise exc
  File "/Library/Frameworks/Python.framework/Versions/3.10/lib/python3.10/site-packages/starlette/_exception_handler.py", line 53, in wrapped_app
    await app(scope, receive, sender)
  File "/Library/Frameworks/Python.framework/Versions/3.10/lib/python3.10/site-packages/starlette/routing.py", line 762, in __call__
    await self.middleware_stack(scope, receive, send)
  File "/Library/Frameworks/Python.framework/Versions/3.10/lib/python3.10/site-packages/starlette/routing.py", line 782, in app
    await route.handle(scope, receive, send)
  File "/Library/Frameworks/Python.framework/Versions/3.10/lib/python3.10/site-packages/starlette/routing.py", line 297, in handle
    await self.app(scope, receive, send)
  File "/Library/Frameworks/Python.framework/Versions/3.10/lib/python3.10/site-packages/starlette/routing.py", line 77, in app
    await wrap_app_handling_exceptions(app, request)(scope, receive, send)
  File "/Library/Frameworks/Python.framework/Versions/3.10/lib/python3.10/site-packages/starlette/_exception_handler.py", line 64, in wrapped_app
    raise exc
  File "/Library/Frameworks/Python.framework/Versions/3.10/lib/python3.10/site-packages/starlette/_exception_handler.py", line 53, in wrapped_app
    await app(scope, receive, sender)
  File "/Library/Frameworks/Python.framework/Versions/3.10/lib/python3.10/site-packages/starlette/routing.py", line 72, in app
    response = await func(request)
  File "/Library/Frameworks/Python.framework/Versions/3.10/lib/python3.10/site-packages/fastapi/routing.py", line 299, in app
    raise e
  File "/Library/Frameworks/Python.framework/Versions/3.10/lib/python3.10/site-packages/fastapi/routing.py", line 294, in app
    raw_response = await run_endpoint_function(
  File "/Library/Frameworks/Python.framework/Versions/3.10/lib/python3.10/site-packages/fastapi/routing.py", line 193, in run_endpoint_function
    return await run_in_threadpool(dependant.call, **values)
  File "/Library/Frameworks/Python.framework/Versions/3.10/lib/python3.10/site-packages/starlette/concurrency.py", line 40, in run_in_threadpool
    return await anyio.to_thread.run_sync(func, *args)
  File "/Library/Frameworks/Python.framework/Versions/3.10/lib/python3.10/site-packages/anyio/to_thread.py", line 56, in run_sync
    return await get_async_backend().run_sync_in_worker_thread(
  File "/Library/Frameworks/Python.framework/Versions/3.10/lib/python3.10/site-packages/anyio/_backends/_asyncio.py", line 2134, in run_sync_in_worker_thread
    return await future
  File "/Library/Frameworks/Python.framework/Versions/3.10/lib/python3.10/site-packages/anyio/_backends/_asyncio.py", line 851, in run
    result = context.run(func, *args)
  File "/Library/Frameworks/Python.framework/Versions/3.10/lib/python3.10/site-packages/chromadb/telemetry/opentelemetry/__init__.py", line 127, in wrapper
    return f(*args, **kwargs)
  File "/Library/Frameworks/Python.framework/Versions/3.10/lib/python3.10/site-packages/chromadb/auth/fastapi.py", line 234, in wrapped
    return f(*args, **kwargs)
  File "/Library/Frameworks/Python.framework/Versions/3.10/lib/python3.10/site-packages/chromadb/server/fastapi/__init__.py", line 568, in delete
    return self._api._delete(
  File "/Library/Frameworks/Python.framework/Versions/3.10/lib/python3.10/site-packages/chromadb/telemetry/opentelemetry/__init__.py", line 127, in wrapper
    return f(*args, **kwargs)
  File "/Library/Frameworks/Python.framework/Versions/3.10/lib/python3.10/site-packages/chromadb/api/segment.py", line 599, in _delete
    raise ValueError(
ValueError: 
                You must provide either ids, where, or where_document to delete. If
                you want to delete all data in a collection you can delete the
                collection itself using the delete_collection method. Or alternatively,
                you can get() all the relevant ids and then delete them.
                
[32mINFO[0m:     [29-01-2024 15:41:19] ::1:60328 - "POST /api/v1/collections/e1e16209-8f4d-461c-bc8b-6b4c5fd7829b/delete HTTP/1.1" 500
[32mINFO[0m:     [29-01-2024 15:41:19] ::1:60328 - "GET /api/v1/collections/e1e16209-8f4d-461c-bc8b-6b4c5fd7829b/count HTTP/1.1" 200
[32mINFO[0m:     [29-01-2024 15:46:15] ::1:61619 - "POST /api/v1/collections?tenant=default_tenant&database=default_database HTTP/1.1" 200
[32mINFO[0m:     [29-01-2024 15:46:15] ::1:61620 - "POST /api/v1/collections/e1e16209-8f4d-461c-bc8b-6b4c5fd7829b/get HTTP/1.1" 200
[31mERROR[0m:    [29-01-2024 15:46:15] 
                You must provide either ids, where, or where_document to delete. If
                you want to delete all data in a collection you can delete the
                collection itself using the delete_collection method. Or alternatively,
                you can get() all the relevant ids and then delete them.
                
Traceback (most recent call last):
  File "/Library/Frameworks/Python.framework/Versions/3.10/lib/python3.10/site-packages/anyio/streams/memory.py", line 97, in receive
    return self.receive_nowait()
  File "/Library/Frameworks/Python.framework/Versions/3.10/lib/python3.10/site-packages/anyio/streams/memory.py", line 92, in receive_nowait
    raise WouldBlock
anyio.WouldBlock

During handling of the above exception, another exception occurred:

Traceback (most recent call last):
  File "/Library/Frameworks/Python.framework/Versions/3.10/lib/python3.10/site-packages/starlette/middleware/base.py", line 159, in call_next
    message = await recv_stream.receive()
  File "/Library/Frameworks/Python.framework/Versions/3.10/lib/python3.10/site-packages/anyio/streams/memory.py", line 112, in receive
    raise EndOfStream
anyio.EndOfStream

During handling of the above exception, another exception occurred:

Traceback (most recent call last):
  File "/Library/Frameworks/Python.framework/Versions/3.10/lib/python3.10/site-packages/chromadb/server/fastapi/__init__.py", line 80, in catch_exceptions_middleware
    return await call_next(request)
  File "/Library/Frameworks/Python.framework/Versions/3.10/lib/python3.10/site-packages/starlette/middleware/base.py", line 165, in call_next
    raise app_exc
  File "/Library/Frameworks/Python.framework/Versions/3.10/lib/python3.10/site-packages/starlette/middleware/base.py", line 151, in coro
    await self.app(scope, receive_or_disconnect, send_no_error)
  File "/Library/Frameworks/Python.framework/Versions/3.10/lib/python3.10/site-packages/starlette/middleware/base.py", line 189, in __call__
    with collapse_excgroups():
  File "/Library/Frameworks/Python.framework/Versions/3.10/lib/python3.10/contextlib.py", line 153, in __exit__
    self.gen.throw(typ, value, traceback)
  File "/Library/Frameworks/Python.framework/Versions/3.10/lib/python3.10/site-packages/starlette/_utils.py", line 91, in collapse_excgroups
    raise exc
  File "/Library/Frameworks/Python.framework/Versions/3.10/lib/python3.10/site-packages/starlette/middleware/base.py", line 191, in __call__
    response = await self.dispatch_func(request, call_next)
  File "/Library/Frameworks/Python.framework/Versions/3.10/lib/python3.10/site-packages/chromadb/server/fastapi/__init__.py", line 94, in check_http_version_middleware
    return await call_next(request)
  File "/Library/Frameworks/Python.framework/Versions/3.10/lib/python3.10/site-packages/starlette/middleware/base.py", line 165, in call_next
    raise app_exc
  File "/Library/Frameworks/Python.framework/Versions/3.10/lib/python3.10/site-packages/starlette/middleware/base.py", line 151, in coro
    await self.app(scope, receive_or_disconnect, send_no_error)
  File "/Library/Frameworks/Python.framework/Versions/3.10/lib/python3.10/site-packages/starlette/middleware/exceptions.py", line 62, in __call__
    await wrap_app_handling_exceptions(self.app, conn)(scope, receive, send)
  File "/Library/Frameworks/Python.framework/Versions/3.10/lib/python3.10/site-packages/starlette/_exception_handler.py", line 64, in wrapped_app
    raise exc
  File "/Library/Frameworks/Python.framework/Versions/3.10/lib/python3.10/site-packages/starlette/_exception_handler.py", line 53, in wrapped_app
    await app(scope, receive, sender)
  File "/Library/Frameworks/Python.framework/Versions/3.10/lib/python3.10/site-packages/starlette/routing.py", line 762, in __call__
    await self.middleware_stack(scope, receive, send)
  File "/Library/Frameworks/Python.framework/Versions/3.10/lib/python3.10/site-packages/starlette/routing.py", line 782, in app
    await route.handle(scope, receive, send)
  File "/Library/Frameworks/Python.framework/Versions/3.10/lib/python3.10/site-packages/starlette/routing.py", line 297, in handle
    await self.app(scope, receive, send)
  File "/Library/Frameworks/Python.framework/Versions/3.10/lib/python3.10/site-packages/starlette/routing.py", line 77, in app
    await wrap_app_handling_exceptions(app, request)(scope, receive, send)
  File "/Library/Frameworks/Python.framework/Versions/3.10/lib/python3.10/site-packages/starlette/_exception_handler.py", line 64, in wrapped_app
    raise exc
  File "/Library/Frameworks/Python.framework/Versions/3.10/lib/python3.10/site-packages/starlette/_exception_handler.py", line 53, in wrapped_app
    await app(scope, receive, sender)
  File "/Library/Frameworks/Python.framework/Versions/3.10/lib/python3.10/site-packages/starlette/routing.py", line 72, in app
    response = await func(request)
  File "/Library/Frameworks/Python.framework/Versions/3.10/lib/python3.10/site-packages/fastapi/routing.py", line 299, in app
    raise e
  File "/Library/Frameworks/Python.framework/Versions/3.10/lib/python3.10/site-packages/fastapi/routing.py", line 294, in app
    raw_response = await run_endpoint_function(
  File "/Library/Frameworks/Python.framework/Versions/3.10/lib/python3.10/site-packages/fastapi/routing.py", line 193, in run_endpoint_function
    return await run_in_threadpool(dependant.call, **values)
  File "/Library/Frameworks/Python.framework/Versions/3.10/lib/python3.10/site-packages/starlette/concurrency.py", line 40, in run_in_threadpool
    return await anyio.to_thread.run_sync(func, *args)
  File "/Library/Frameworks/Python.framework/Versions/3.10/lib/python3.10/site-packages/anyio/to_thread.py", line 56, in run_sync
    return await get_async_backend().run_sync_in_worker_thread(
  File "/Library/Frameworks/Python.framework/Versions/3.10/lib/python3.10/site-packages/anyio/_backends/_asyncio.py", line 2134, in run_sync_in_worker_thread
    return await future
  File "/Library/Frameworks/Python.framework/Versions/3.10/lib/python3.10/site-packages/anyio/_backends/_asyncio.py", line 851, in run
    result = context.run(func, *args)
  File "/Library/Frameworks/Python.framework/Versions/3.10/lib/python3.10/site-packages/chromadb/telemetry/opentelemetry/__init__.py", line 127, in wrapper
    return f(*args, **kwargs)
  File "/Library/Frameworks/Python.framework/Versions/3.10/lib/python3.10/site-packages/chromadb/auth/fastapi.py", line 234, in wrapped
    return f(*args, **kwargs)
  File "/Library/Frameworks/Python.framework/Versions/3.10/lib/python3.10/site-packages/chromadb/server/fastapi/__init__.py", line 568, in delete
    return self._api._delete(
  File "/Library/Frameworks/Python.framework/Versions/3.10/lib/python3.10/site-packages/chromadb/telemetry/opentelemetry/__init__.py", line 127, in wrapper
    return f(*args, **kwargs)
  File "/Library/Frameworks/Python.framework/Versions/3.10/lib/python3.10/site-packages/chromadb/api/segment.py", line 599, in _delete
    raise ValueError(
ValueError: 
                You must provide either ids, where, or where_document to delete. If
                you want to delete all data in a collection you can delete the
                collection itself using the delete_collection method. Or alternatively,
                you can get() all the relevant ids and then delete them.
                
[32mINFO[0m:     [29-01-2024 15:46:15] ::1:61619 - "POST /api/v1/collections/e1e16209-8f4d-461c-bc8b-6b4c5fd7829b/delete HTTP/1.1" 500
[32mINFO[0m:     [29-01-2024 15:46:15] ::1:61619 - "GET /api/v1/collections/e1e16209-8f4d-461c-bc8b-6b4c5fd7829b/count HTTP/1.1" 200
[31mERROR[0m:    [29-01-2024 16:23:22] Failed to set chroma_server_nofile to 65535: current limit exceeds maximum limit nofile soft limit will remain at 10240
[32mINFO[0m:     [29-01-2024 16:23:22] Anonymized telemetry enabled. See                     https://docs.trychroma.com/telemetry for more information.
[36mDEBUG[0m:    [29-01-2024 16:23:22] Starting component System
[36mDEBUG[0m:    [29-01-2024 16:23:22] Starting component OpenTelemetryClient
[36mDEBUG[0m:    [29-01-2024 16:23:22] Starting component SimpleAssignmentPolicy
[36mDEBUG[0m:    [29-01-2024 16:23:22] Starting component SqliteDB
[36mDEBUG[0m:    [29-01-2024 16:23:22] Starting component Posthog
[36mDEBUG[0m:    [29-01-2024 16:23:22] Starting component LocalSegmentManager
[36mDEBUG[0m:    [29-01-2024 16:23:22] Starting component SegmentAPI
[32mINFO[0m:     [29-01-2024 16:23:22] Started server process [[36m64870[0m]
[32mINFO[0m:     [29-01-2024 16:23:22] Waiting for application startup.
[32mINFO[0m:     [29-01-2024 16:23:22] Application startup complete.
[32mINFO[0m:     [29-01-2024 16:23:22] Uvicorn running on [1mhttp://localhost:8000[0m (Press CTRL+C to quit)
[32mINFO[0m:     [29-01-2024 16:23:52] ::1:54443 - "POST /api/v1/collections?tenant=default_tenant&database=default_database HTTP/1.1" 200
[32mINFO[0m:     [29-01-2024 16:23:52] ::1:54447 - "POST /api/v1/collections/e1e16209-8f4d-461c-bc8b-6b4c5fd7829b/get HTTP/1.1" 200
[31mERROR[0m:    [29-01-2024 16:23:52] 
                You must provide either ids, where, or where_document to delete. If
                you want to delete all data in a collection you can delete the
                collection itself using the delete_collection method. Or alternatively,
                you can get() all the relevant ids and then delete them.
                
Traceback (most recent call last):
  File "/Library/Frameworks/Python.framework/Versions/3.10/lib/python3.10/site-packages/anyio/streams/memory.py", line 97, in receive
    return self.receive_nowait()
  File "/Library/Frameworks/Python.framework/Versions/3.10/lib/python3.10/site-packages/anyio/streams/memory.py", line 92, in receive_nowait
    raise WouldBlock
anyio.WouldBlock

During handling of the above exception, another exception occurred:

Traceback (most recent call last):
  File "/Library/Frameworks/Python.framework/Versions/3.10/lib/python3.10/site-packages/starlette/middleware/base.py", line 159, in call_next
    message = await recv_stream.receive()
  File "/Library/Frameworks/Python.framework/Versions/3.10/lib/python3.10/site-packages/anyio/streams/memory.py", line 112, in receive
    raise EndOfStream
anyio.EndOfStream

During handling of the above exception, another exception occurred:

Traceback (most recent call last):
  File "/Library/Frameworks/Python.framework/Versions/3.10/lib/python3.10/site-packages/chromadb/server/fastapi/__init__.py", line 80, in catch_exceptions_middleware
    return await call_next(request)
  File "/Library/Frameworks/Python.framework/Versions/3.10/lib/python3.10/site-packages/starlette/middleware/base.py", line 165, in call_next
    raise app_exc
  File "/Library/Frameworks/Python.framework/Versions/3.10/lib/python3.10/site-packages/starlette/middleware/base.py", line 151, in coro
    await self.app(scope, receive_or_disconnect, send_no_error)
  File "/Library/Frameworks/Python.framework/Versions/3.10/lib/python3.10/site-packages/starlette/middleware/base.py", line 189, in __call__
    with collapse_excgroups():
  File "/Library/Frameworks/Python.framework/Versions/3.10/lib/python3.10/contextlib.py", line 153, in __exit__
    self.gen.throw(typ, value, traceback)
  File "/Library/Frameworks/Python.framework/Versions/3.10/lib/python3.10/site-packages/starlette/_utils.py", line 91, in collapse_excgroups
    raise exc
  File "/Library/Frameworks/Python.framework/Versions/3.10/lib/python3.10/site-packages/starlette/middleware/base.py", line 191, in __call__
    response = await self.dispatch_func(request, call_next)
  File "/Library/Frameworks/Python.framework/Versions/3.10/lib/python3.10/site-packages/chromadb/server/fastapi/__init__.py", line 94, in check_http_version_middleware
    return await call_next(request)
  File "/Library/Frameworks/Python.framework/Versions/3.10/lib/python3.10/site-packages/starlette/middleware/base.py", line 165, in call_next
    raise app_exc
  File "/Library/Frameworks/Python.framework/Versions/3.10/lib/python3.10/site-packages/starlette/middleware/base.py", line 151, in coro
    await self.app(scope, receive_or_disconnect, send_no_error)
  File "/Library/Frameworks/Python.framework/Versions/3.10/lib/python3.10/site-packages/starlette/middleware/exceptions.py", line 62, in __call__
    await wrap_app_handling_exceptions(self.app, conn)(scope, receive, send)
  File "/Library/Frameworks/Python.framework/Versions/3.10/lib/python3.10/site-packages/starlette/_exception_handler.py", line 64, in wrapped_app
    raise exc
  File "/Library/Frameworks/Python.framework/Versions/3.10/lib/python3.10/site-packages/starlette/_exception_handler.py", line 53, in wrapped_app
    await app(scope, receive, sender)
  File "/Library/Frameworks/Python.framework/Versions/3.10/lib/python3.10/site-packages/starlette/routing.py", line 762, in __call__
    await self.middleware_stack(scope, receive, send)
  File "/Library/Frameworks/Python.framework/Versions/3.10/lib/python3.10/site-packages/starlette/routing.py", line 782, in app
    await route.handle(scope, receive, send)
  File "/Library/Frameworks/Python.framework/Versions/3.10/lib/python3.10/site-packages/starlette/routing.py", line 297, in handle
    await self.app(scope, receive, send)
  File "/Library/Frameworks/Python.framework/Versions/3.10/lib/python3.10/site-packages/starlette/routing.py", line 77, in app
    await wrap_app_handling_exceptions(app, request)(scope, receive, send)
  File "/Library/Frameworks/Python.framework/Versions/3.10/lib/python3.10/site-packages/starlette/_exception_handler.py", line 64, in wrapped_app
    raise exc
  File "/Library/Frameworks/Python.framework/Versions/3.10/lib/python3.10/site-packages/starlette/_exception_handler.py", line 53, in wrapped_app
    await app(scope, receive, sender)
  File "/Library/Frameworks/Python.framework/Versions/3.10/lib/python3.10/site-packages/starlette/routing.py", line 72, in app
    response = await func(request)
  File "/Library/Frameworks/Python.framework/Versions/3.10/lib/python3.10/site-packages/fastapi/routing.py", line 299, in app
    raise e
  File "/Library/Frameworks/Python.framework/Versions/3.10/lib/python3.10/site-packages/fastapi/routing.py", line 294, in app
    raw_response = await run_endpoint_function(
  File "/Library/Frameworks/Python.framework/Versions/3.10/lib/python3.10/site-packages/fastapi/routing.py", line 193, in run_endpoint_function
    return await run_in_threadpool(dependant.call, **values)
  File "/Library/Frameworks/Python.framework/Versions/3.10/lib/python3.10/site-packages/starlette/concurrency.py", line 40, in run_in_threadpool
    return await anyio.to_thread.run_sync(func, *args)
  File "/Library/Frameworks/Python.framework/Versions/3.10/lib/python3.10/site-packages/anyio/to_thread.py", line 56, in run_sync
    return await get_async_backend().run_sync_in_worker_thread(
  File "/Library/Frameworks/Python.framework/Versions/3.10/lib/python3.10/site-packages/anyio/_backends/_asyncio.py", line 2134, in run_sync_in_worker_thread
    return await future
  File "/Library/Frameworks/Python.framework/Versions/3.10/lib/python3.10/site-packages/anyio/_backends/_asyncio.py", line 851, in run
    result = context.run(func, *args)
  File "/Library/Frameworks/Python.framework/Versions/3.10/lib/python3.10/site-packages/chromadb/telemetry/opentelemetry/__init__.py", line 127, in wrapper
    return f(*args, **kwargs)
  File "/Library/Frameworks/Python.framework/Versions/3.10/lib/python3.10/site-packages/chromadb/auth/fastapi.py", line 234, in wrapped
    return f(*args, **kwargs)
  File "/Library/Frameworks/Python.framework/Versions/3.10/lib/python3.10/site-packages/chromadb/server/fastapi/__init__.py", line 568, in delete
    return self._api._delete(
  File "/Library/Frameworks/Python.framework/Versions/3.10/lib/python3.10/site-packages/chromadb/telemetry/opentelemetry/__init__.py", line 127, in wrapper
    return f(*args, **kwargs)
  File "/Library/Frameworks/Python.framework/Versions/3.10/lib/python3.10/site-packages/chromadb/api/segment.py", line 599, in _delete
    raise ValueError(
ValueError: 
                You must provide either ids, where, or where_document to delete. If
                you want to delete all data in a collection you can delete the
                collection itself using the delete_collection method. Or alternatively,
                you can get() all the relevant ids and then delete them.
                
[32mINFO[0m:     [29-01-2024 16:23:52] ::1:54443 - "POST /api/v1/collections/e1e16209-8f4d-461c-bc8b-6b4c5fd7829b/delete HTTP/1.1" 500
[32mINFO[0m:     [29-01-2024 16:23:52] ::1:54443 - "GET /api/v1/collections/e1e16209-8f4d-461c-bc8b-6b4c5fd7829b/count HTTP/1.1" 200
[32mINFO[0m:     [29-01-2024 17:16:48] ::1:61816 - "POST /api/v1/collections?tenant=default_tenant&database=default_database HTTP/1.1" 200
[32mINFO[0m:     [29-01-2024 17:16:48] ::1:61817 - "POST /api/v1/collections/e1e16209-8f4d-461c-bc8b-6b4c5fd7829b/get HTTP/1.1" 200
[31mERROR[0m:    [29-01-2024 17:16:48] 
                You must provide either ids, where, or where_document to delete. If
                you want to delete all data in a collection you can delete the
                collection itself using the delete_collection method. Or alternatively,
                you can get() all the relevant ids and then delete them.
                
Traceback (most recent call last):
  File "/Library/Frameworks/Python.framework/Versions/3.10/lib/python3.10/site-packages/anyio/streams/memory.py", line 97, in receive
    return self.receive_nowait()
  File "/Library/Frameworks/Python.framework/Versions/3.10/lib/python3.10/site-packages/anyio/streams/memory.py", line 92, in receive_nowait
    raise WouldBlock
anyio.WouldBlock

During handling of the above exception, another exception occurred:

Traceback (most recent call last):
  File "/Library/Frameworks/Python.framework/Versions/3.10/lib/python3.10/site-packages/starlette/middleware/base.py", line 159, in call_next
    message = await recv_stream.receive()
  File "/Library/Frameworks/Python.framework/Versions/3.10/lib/python3.10/site-packages/anyio/streams/memory.py", line 112, in receive
    raise EndOfStream
anyio.EndOfStream

During handling of the above exception, another exception occurred:

Traceback (most recent call last):
  File "/Library/Frameworks/Python.framework/Versions/3.10/lib/python3.10/site-packages/chromadb/server/fastapi/__init__.py", line 80, in catch_exceptions_middleware
    return await call_next(request)
  File "/Library/Frameworks/Python.framework/Versions/3.10/lib/python3.10/site-packages/starlette/middleware/base.py", line 165, in call_next
    raise app_exc
  File "/Library/Frameworks/Python.framework/Versions/3.10/lib/python3.10/site-packages/starlette/middleware/base.py", line 151, in coro
    await self.app(scope, receive_or_disconnect, send_no_error)
  File "/Library/Frameworks/Python.framework/Versions/3.10/lib/python3.10/site-packages/starlette/middleware/base.py", line 189, in __call__
    with collapse_excgroups():
  File "/Library/Frameworks/Python.framework/Versions/3.10/lib/python3.10/contextlib.py", line 153, in __exit__
    self.gen.throw(typ, value, traceback)
  File "/Library/Frameworks/Python.framework/Versions/3.10/lib/python3.10/site-packages/starlette/_utils.py", line 91, in collapse_excgroups
    raise exc
  File "/Library/Frameworks/Python.framework/Versions/3.10/lib/python3.10/site-packages/starlette/middleware/base.py", line 191, in __call__
    response = await self.dispatch_func(request, call_next)
  File "/Library/Frameworks/Python.framework/Versions/3.10/lib/python3.10/site-packages/chromadb/server/fastapi/__init__.py", line 94, in check_http_version_middleware
    return await call_next(request)
  File "/Library/Frameworks/Python.framework/Versions/3.10/lib/python3.10/site-packages/starlette/middleware/base.py", line 165, in call_next
    raise app_exc
  File "/Library/Frameworks/Python.framework/Versions/3.10/lib/python3.10/site-packages/starlette/middleware/base.py", line 151, in coro
    await self.app(scope, receive_or_disconnect, send_no_error)
  File "/Library/Frameworks/Python.framework/Versions/3.10/lib/python3.10/site-packages/starlette/middleware/exceptions.py", line 62, in __call__
    await wrap_app_handling_exceptions(self.app, conn)(scope, receive, send)
  File "/Library/Frameworks/Python.framework/Versions/3.10/lib/python3.10/site-packages/starlette/_exception_handler.py", line 64, in wrapped_app
    raise exc
  File "/Library/Frameworks/Python.framework/Versions/3.10/lib/python3.10/site-packages/starlette/_exception_handler.py", line 53, in wrapped_app
    await app(scope, receive, sender)
  File "/Library/Frameworks/Python.framework/Versions/3.10/lib/python3.10/site-packages/starlette/routing.py", line 762, in __call__
    await self.middleware_stack(scope, receive, send)
  File "/Library/Frameworks/Python.framework/Versions/3.10/lib/python3.10/site-packages/starlette/routing.py", line 782, in app
    await route.handle(scope, receive, send)
  File "/Library/Frameworks/Python.framework/Versions/3.10/lib/python3.10/site-packages/starlette/routing.py", line 297, in handle
    await self.app(scope, receive, send)
  File "/Library/Frameworks/Python.framework/Versions/3.10/lib/python3.10/site-packages/starlette/routing.py", line 77, in app
    await wrap_app_handling_exceptions(app, request)(scope, receive, send)
  File "/Library/Frameworks/Python.framework/Versions/3.10/lib/python3.10/site-packages/starlette/_exception_handler.py", line 64, in wrapped_app
    raise exc
  File "/Library/Frameworks/Python.framework/Versions/3.10/lib/python3.10/site-packages/starlette/_exception_handler.py", line 53, in wrapped_app
    await app(scope, receive, sender)
  File "/Library/Frameworks/Python.framework/Versions/3.10/lib/python3.10/site-packages/starlette/routing.py", line 72, in app
    response = await func(request)
  File "/Library/Frameworks/Python.framework/Versions/3.10/lib/python3.10/site-packages/fastapi/routing.py", line 299, in app
    raise e
  File "/Library/Frameworks/Python.framework/Versions/3.10/lib/python3.10/site-packages/fastapi/routing.py", line 294, in app
    raw_response = await run_endpoint_function(
  File "/Library/Frameworks/Python.framework/Versions/3.10/lib/python3.10/site-packages/fastapi/routing.py", line 193, in run_endpoint_function
    return await run_in_threadpool(dependant.call, **values)
  File "/Library/Frameworks/Python.framework/Versions/3.10/lib/python3.10/site-packages/starlette/concurrency.py", line 40, in run_in_threadpool
    return await anyio.to_thread.run_sync(func, *args)
  File "/Library/Frameworks/Python.framework/Versions/3.10/lib/python3.10/site-packages/anyio/to_thread.py", line 56, in run_sync
    return await get_async_backend().run_sync_in_worker_thread(
  File "/Library/Frameworks/Python.framework/Versions/3.10/lib/python3.10/site-packages/anyio/_backends/_asyncio.py", line 2134, in run_sync_in_worker_thread
    return await future
  File "/Library/Frameworks/Python.framework/Versions/3.10/lib/python3.10/site-packages/anyio/_backends/_asyncio.py", line 851, in run
    result = context.run(func, *args)
  File "/Library/Frameworks/Python.framework/Versions/3.10/lib/python3.10/site-packages/chromadb/telemetry/opentelemetry/__init__.py", line 127, in wrapper
    return f(*args, **kwargs)
  File "/Library/Frameworks/Python.framework/Versions/3.10/lib/python3.10/site-packages/chromadb/auth/fastapi.py", line 234, in wrapped
    return f(*args, **kwargs)
  File "/Library/Frameworks/Python.framework/Versions/3.10/lib/python3.10/site-packages/chromadb/server/fastapi/__init__.py", line 568, in delete
    return self._api._delete(
  File "/Library/Frameworks/Python.framework/Versions/3.10/lib/python3.10/site-packages/chromadb/telemetry/opentelemetry/__init__.py", line 127, in wrapper
    return f(*args, **kwargs)
  File "/Library/Frameworks/Python.framework/Versions/3.10/lib/python3.10/site-packages/chromadb/api/segment.py", line 599, in _delete
    raise ValueError(
ValueError: 
                You must provide either ids, where, or where_document to delete. If
                you want to delete all data in a collection you can delete the
                collection itself using the delete_collection method. Or alternatively,
                you can get() all the relevant ids and then delete them.
                
[32mINFO[0m:     [29-01-2024 17:16:48] ::1:61816 - "POST /api/v1/collections/e1e16209-8f4d-461c-bc8b-6b4c5fd7829b/delete HTTP/1.1" 500
[32mINFO[0m:     [29-01-2024 17:16:48] ::1:61816 - "GET /api/v1/collections/e1e16209-8f4d-461c-bc8b-6b4c5fd7829b/count HTTP/1.1" 200
[32mINFO[0m:     [29-01-2024 17:18:34] ::1:61867 - "POST /api/v1/collections?tenant=default_tenant&database=default_database HTTP/1.1" 200
[32mINFO[0m:     [29-01-2024 17:18:34] ::1:61868 - "POST /api/v1/collections/e1e16209-8f4d-461c-bc8b-6b4c5fd7829b/get HTTP/1.1" 200
[31mERROR[0m:    [29-01-2024 17:18:34] 
                You must provide either ids, where, or where_document to delete. If
                you want to delete all data in a collection you can delete the
                collection itself using the delete_collection method. Or alternatively,
                you can get() all the relevant ids and then delete them.
                
Traceback (most recent call last):
  File "/Library/Frameworks/Python.framework/Versions/3.10/lib/python3.10/site-packages/anyio/streams/memory.py", line 97, in receive
    return self.receive_nowait()
  File "/Library/Frameworks/Python.framework/Versions/3.10/lib/python3.10/site-packages/anyio/streams/memory.py", line 92, in receive_nowait
    raise WouldBlock
anyio.WouldBlock

During handling of the above exception, another exception occurred:

Traceback (most recent call last):
  File "/Library/Frameworks/Python.framework/Versions/3.10/lib/python3.10/site-packages/starlette/middleware/base.py", line 159, in call_next
    message = await recv_stream.receive()
  File "/Library/Frameworks/Python.framework/Versions/3.10/lib/python3.10/site-packages/anyio/streams/memory.py", line 112, in receive
    raise EndOfStream
anyio.EndOfStream

During handling of the above exception, another exception occurred:

Traceback (most recent call last):
  File "/Library/Frameworks/Python.framework/Versions/3.10/lib/python3.10/site-packages/chromadb/server/fastapi/__init__.py", line 80, in catch_exceptions_middleware
    return await call_next(request)
  File "/Library/Frameworks/Python.framework/Versions/3.10/lib/python3.10/site-packages/starlette/middleware/base.py", line 165, in call_next
    raise app_exc
  File "/Library/Frameworks/Python.framework/Versions/3.10/lib/python3.10/site-packages/starlette/middleware/base.py", line 151, in coro
    await self.app(scope, receive_or_disconnect, send_no_error)
  File "/Library/Frameworks/Python.framework/Versions/3.10/lib/python3.10/site-packages/starlette/middleware/base.py", line 189, in __call__
    with collapse_excgroups():
  File "/Library/Frameworks/Python.framework/Versions/3.10/lib/python3.10/contextlib.py", line 153, in __exit__
    self.gen.throw(typ, value, traceback)
  File "/Library/Frameworks/Python.framework/Versions/3.10/lib/python3.10/site-packages/starlette/_utils.py", line 91, in collapse_excgroups
    raise exc
  File "/Library/Frameworks/Python.framework/Versions/3.10/lib/python3.10/site-packages/starlette/middleware/base.py", line 191, in __call__
    response = await self.dispatch_func(request, call_next)
  File "/Library/Frameworks/Python.framework/Versions/3.10/lib/python3.10/site-packages/chromadb/server/fastapi/__init__.py", line 94, in check_http_version_middleware
    return await call_next(request)
  File "/Library/Frameworks/Python.framework/Versions/3.10/lib/python3.10/site-packages/starlette/middleware/base.py", line 165, in call_next
    raise app_exc
  File "/Library/Frameworks/Python.framework/Versions/3.10/lib/python3.10/site-packages/starlette/middleware/base.py", line 151, in coro
    await self.app(scope, receive_or_disconnect, send_no_error)
  File "/Library/Frameworks/Python.framework/Versions/3.10/lib/python3.10/site-packages/starlette/middleware/exceptions.py", line 62, in __call__
    await wrap_app_handling_exceptions(self.app, conn)(scope, receive, send)
  File "/Library/Frameworks/Python.framework/Versions/3.10/lib/python3.10/site-packages/starlette/_exception_handler.py", line 64, in wrapped_app
    raise exc
  File "/Library/Frameworks/Python.framework/Versions/3.10/lib/python3.10/site-packages/starlette/_exception_handler.py", line 53, in wrapped_app
    await app(scope, receive, sender)
  File "/Library/Frameworks/Python.framework/Versions/3.10/lib/python3.10/site-packages/starlette/routing.py", line 762, in __call__
    await self.middleware_stack(scope, receive, send)
  File "/Library/Frameworks/Python.framework/Versions/3.10/lib/python3.10/site-packages/starlette/routing.py", line 782, in app
    await route.handle(scope, receive, send)
  File "/Library/Frameworks/Python.framework/Versions/3.10/lib/python3.10/site-packages/starlette/routing.py", line 297, in handle
    await self.app(scope, receive, send)
  File "/Library/Frameworks/Python.framework/Versions/3.10/lib/python3.10/site-packages/starlette/routing.py", line 77, in app
    await wrap_app_handling_exceptions(app, request)(scope, receive, send)
  File "/Library/Frameworks/Python.framework/Versions/3.10/lib/python3.10/site-packages/starlette/_exception_handler.py", line 64, in wrapped_app
    raise exc
  File "/Library/Frameworks/Python.framework/Versions/3.10/lib/python3.10/site-packages/starlette/_exception_handler.py", line 53, in wrapped_app
    await app(scope, receive, sender)
  File "/Library/Frameworks/Python.framework/Versions/3.10/lib/python3.10/site-packages/starlette/routing.py", line 72, in app
    response = await func(request)
  File "/Library/Frameworks/Python.framework/Versions/3.10/lib/python3.10/site-packages/fastapi/routing.py", line 299, in app
    raise e
  File "/Library/Frameworks/Python.framework/Versions/3.10/lib/python3.10/site-packages/fastapi/routing.py", line 294, in app
    raw_response = await run_endpoint_function(
  File "/Library/Frameworks/Python.framework/Versions/3.10/lib/python3.10/site-packages/fastapi/routing.py", line 193, in run_endpoint_function
    return await run_in_threadpool(dependant.call, **values)
  File "/Library/Frameworks/Python.framework/Versions/3.10/lib/python3.10/site-packages/starlette/concurrency.py", line 40, in run_in_threadpool
    return await anyio.to_thread.run_sync(func, *args)
  File "/Library/Frameworks/Python.framework/Versions/3.10/lib/python3.10/site-packages/anyio/to_thread.py", line 56, in run_sync
    return await get_async_backend().run_sync_in_worker_thread(
  File "/Library/Frameworks/Python.framework/Versions/3.10/lib/python3.10/site-packages/anyio/_backends/_asyncio.py", line 2134, in run_sync_in_worker_thread
    return await future
  File "/Library/Frameworks/Python.framework/Versions/3.10/lib/python3.10/site-packages/anyio/_backends/_asyncio.py", line 851, in run
    result = context.run(func, *args)
  File "/Library/Frameworks/Python.framework/Versions/3.10/lib/python3.10/site-packages/chromadb/telemetry/opentelemetry/__init__.py", line 127, in wrapper
    return f(*args, **kwargs)
  File "/Library/Frameworks/Python.framework/Versions/3.10/lib/python3.10/site-packages/chromadb/auth/fastapi.py", line 234, in wrapped
    return f(*args, **kwargs)
  File "/Library/Frameworks/Python.framework/Versions/3.10/lib/python3.10/site-packages/chromadb/server/fastapi/__init__.py", line 568, in delete
    return self._api._delete(
  File "/Library/Frameworks/Python.framework/Versions/3.10/lib/python3.10/site-packages/chromadb/telemetry/opentelemetry/__init__.py", line 127, in wrapper
    return f(*args, **kwargs)
  File "/Library/Frameworks/Python.framework/Versions/3.10/lib/python3.10/site-packages/chromadb/api/segment.py", line 599, in _delete
    raise ValueError(
ValueError: 
                You must provide either ids, where, or where_document to delete. If
                you want to delete all data in a collection you can delete the
                collection itself using the delete_collection method. Or alternatively,
                you can get() all the relevant ids and then delete them.
                
[32mINFO[0m:     [29-01-2024 17:18:34] ::1:61867 - "POST /api/v1/collections/e1e16209-8f4d-461c-bc8b-6b4c5fd7829b/delete HTTP/1.1" 500
[32mINFO[0m:     [29-01-2024 17:18:34] ::1:61867 - "GET /api/v1/collections/e1e16209-8f4d-461c-bc8b-6b4c5fd7829b/count HTTP/1.1" 200
[31mERROR[0m:    [29-01-2024 17:25:22] Failed to set chroma_server_nofile to 65535: current limit exceeds maximum limit nofile soft limit will remain at 10240
[32mINFO[0m:     [29-01-2024 17:25:22] Anonymized telemetry enabled. See                     https://docs.trychroma.com/telemetry for more information.
[36mDEBUG[0m:    [29-01-2024 17:25:22] Starting component System
[36mDEBUG[0m:    [29-01-2024 17:25:22] Starting component OpenTelemetryClient
[36mDEBUG[0m:    [29-01-2024 17:25:22] Starting component SimpleAssignmentPolicy
[36mDEBUG[0m:    [29-01-2024 17:25:22] Starting component SqliteDB
[36mDEBUG[0m:    [29-01-2024 17:25:22] Starting component Posthog
[36mDEBUG[0m:    [29-01-2024 17:25:22] Starting component LocalSegmentManager
[36mDEBUG[0m:    [29-01-2024 17:25:22] Starting component SegmentAPI
[32mINFO[0m:     [29-01-2024 17:25:22] Started server process [[36m65796[0m]
[32mINFO[0m:     [29-01-2024 17:25:22] Waiting for application startup.
[32mINFO[0m:     [29-01-2024 17:25:22] Application startup complete.
[32mINFO[0m:     [29-01-2024 17:25:22] Uvicorn running on [1mhttp://localhost:8000[0m (Press CTRL+C to quit)
